Workbook

Sheet Marketplace Tasks
A1: Task ID | B1: Phase | C1: Type | D1: Task Title | E1: Description | F1: Reference (if any) | G1: Assigned To | H1: Status | I1: Notes
A2: TSK-001 | B2: Phase 0 - Foundations | C2: Backend | D2: Design seller identity model | E2: Decide whether sellers can be individual creators (not just verified brands) before writing the catalog service — this changes several foreign keys. | F2: m
A3: TSK-002 | B3: Phase 0 - Foundations | C3: Backend | D3: Migration: merch_products & merch_variants tables | E3: Create merch_products and merch_variants tables (SKU, size/color variants, pricing in INR/USD cents, stock_qty, weight, print_file_url, artwork_id link). | F3: Section 04 - Schema additions
A4: TSK-003 | B4: Phase 0 - Foundations | C4: Backend | D4: Migration: print_providers table | E4: Create print_providers table to store POD partner config (Printful/Printify/manual) with integration_type and api_config jsonb. | F4: Section 04 - Schema additions
A5: TSK-004 | B5: Phase 0 - Foundations | C5: Backend | D5: Seller onboarding API + KYC service | E5: Build onboarding API endpoints for new sellers, reusing brand_verification_requests pattern for KYC/KYB where applicable. | F5: Section 01 - Existing INFRA / Section 07 Q1
A6: TSK-005 | B6: Phase 0 - Foundations | C6: Frontend | D6: Seller onboarding UI flow | E6: Build the multi-step seller onboarding screens (profile, payout details, KYC document upload, verification status) consuming the onboarding API. | F6: Section 01 - Existing INFRA / Section 07 Q1
A7: TSK-006 | B7: Phase 0 - Foundations | C7: Frontend | D7: Seller dashboard shell | E7: Scaffold the seller dashboard shell/navigation (products, orders, payouts placeholders) that later phases will fill in. | F7: Section 06 - Phase 0 deliverables
A8: TSK-007 | B8: Phase 1 - Standalone Merch | C8: Backend | D8: Build carts & cart_items tables + API | E8: Create carts and cart_items tables and CRUD endpoints to support persistent multi-item, multi-seller shopping carts (item_type: license or merch_variant). | F8: Section 04 - Checkout schema
A9: TSK-008 | B9: Phase 1 - Standalone Merch | C9: Backend | D9: Split order_items by seller_id | E9: Add seller_id, item_type, merch_variant_id, and cart_id columns to orders/order_items so a single order can span multiple sellers. | F9: Section 04 - Checkout schema
A10: TSK-009 | B10: Phase 1 - Standalone Merch | C10: Backend | D10: Build addresses table + API | E10: Create addresses table and endpoints for buyer shipping addresses (line1/2, city, state, postal_code, country, is_default). | F10: Section 04 - Fulfillment schema
A11: TSK-010 | B11: Phase 1 - Standalone Merch | C11: Backend | D11: Build fulfillments table + manual status update API | E11: Create fulfillments and fulfillment_items tables with manual status update endpoints (fulfillment_type = in_house_stock, no POD integration yet). | F11: Section 06 - Phase 1 deliverables
A12: TSK-011 | B12: Phase 1 - Standalone Merch | C12: Backend | D12: Merch catalog listing API | E12: Build read APIs for browsing/searching the small standalone merch catalog (product + variant listing, filters). | F12: Section 06 - Phase 1
A13: TSK-012 | B13: Phase 1 - Standalone Merch | C13: Frontend | D13: Merch catalog browse & product detail pages | E13: Build the storefront pages for browsing merch products, filtering, and viewing a product detail page with variant (size/color) selection. | F13: Section 06 - Phase 1
... A35: TSK-034 | B35: Cross-cutting / Open Questions | C35: Frontend | D35: API contract review with frontend team | E35: Frontend sync with backend on request/response shapes for cart, checkout, fulfillment, and payouts endpoints before UI build-out per phase. | F35: Section 05 - Service boundaries diagram

Sheet Log Tracker
B1: Dev Log & Tracker
B3: Sprint Week | C3: Task ID/Name | D3: Feature / Project Area | E3: Task Description | F3: Priority | G3: Assigned To | H3: Status | I3: Reviewer | J3: Start Date | K3: Target Completion Date | L3: Completion Date | M3: Pull Request / Merge Link | N3: Progress Notes | O3: Blockers / Issues | P3: Next Steps | Q3: Carry Over to Next Week (Y/N)
B4: 46174 | C4: Dev Log & Tracker | D4: Project Management | E4: Create a spreadsheet for tracking development progress weekly and logging changes to the platform code. | F4: Medium | G4: Joey | H4: Complete | J4: 46174 | K4: 46174 | L4: 46174 | M4: N/A | N4: Completed after our meeting, sent to the team | O4: N/A | P4: Whole team gets on board and starts using this weekly. | Q4: Y
B5: June 5 push | C5: Double footer | D5: Navigation/Menu | E5: Fix the double footers that pop up on multiple pages. | F5: High | G5: Rafay | H5: Complete | J5: 46174 | K5: 46178 | L5: 46181
B6: June 5 push | C6: Update Buttons | D6: Home Page | E6: Buttons: for brands, artists, view active | F6: High | G6: Rafay | H6: Complete | J6: 46174 | K6: 46178 | L6: 46181
B7: June 5 push | C7: Artist Logos | D7: About | E7: Remove empty artist logos | F7: Medium | G7: Rafay | H7: Complete | J7: 46174 | K7: 46178 | L7: 46181
C8: Brand Properties listed | D8: Super Admin | E8: Have Brand properties listed under brand owners | F8: Low | G8: Dhruv | H8: Complete
C9: artist button 404 | D9: Super Admin | E9: artist button 404 fix | F9: Low | G9: Dhruv | H9: Complete
C10: Owner Profile | D10: Brand, Super Admin | E10: Owner profile separate from Brands tab | F10: Low | G10: Dhruv | H10: Complete
C11: Header/Footer | D11: Brand, Navigation/Menu | E11: No header and footer | F11: Low | G11: Rafay | H11: Complete
B12: 46174 | C12: Website Content Doc | D12: Website Content | E12: Create a doc with content for Dhruv to update including: past campaigns, fan artist users, licensed fan work, etc. | F12: High | G12: Joey | H12: In Progress | J12: 46174 | K12: 46175 | M12: N/A
B13: June 5 push | C13: Nav Bar update | D13: Navigation/Menu | E13: Fix Nav bar to be correct pages in web | F13: High | G13: Rafay | H13: Complete | J13: 46174 | L13: 46181 | N13: Desktop verson is complete but mobile version is still old nav bar options.
B14: June 5 push | C14: Button Hover | D14: About | E14: Remove button hover | F14: Medium | G14: Rafay | H14: Complete
B15: June 12 push | C15: Update Image | D15: Guidelines | E15: Update images with ones provided in Whatsapp group | F15: High | G15: Pratyank | H15: Complete | J15: 46181 | L15: 46202
B16: June 12 push | C16: Remove some sections | D16: Guidelines | E16: Remove following sections: Popular IP-Specific Guidelines, Additional Resources | F16: High | G16: Rafay | H16: Complete | J16: 46181 | L16: 46202
B17: June 12 push | C17: Discord link | D17: Guidelines | E17: keep artist community link and add Discord link | F17: Medium | G17: Rafay | H17: Complete | J17: 46181 | L17: 46202
B18: June 12 push | C18: Guidelines PDF | D18: Guidelines | E18: keep addtional resources link to pdf | F18: Medium | G18: Rafay | H18: Complete | J18: 46181 | L18: 46202
B19: June 12 push | C19: Update Section | D19: Guidelines | E19: Update the Ready to submit your fan art? section at the bottom of the page. | F19: High | G19: Pratyank | H19: Complete | J19: 46181 | L19: 46202
B20: June 12 push | C20: Page spacing | D20: Book a Demo | E20: Fix Spacing between top of page and nav bar | F20: Medium | G20: Rafay | H20: Complete | J20: 46181 | L20: 46195 | N20: This is fixed on desktop but still showing issues on mobile.
B21: June 12/22 push | C21: Clean up Mobile | D21: Various Pages | E21: Clean up the spacing of headers on each page for Mobile view | F21: High | G21: Pratyank | H21: Complete | J21: 46189 | L21: 46195
B22: June 12/22 push | C22: Mobile page spacing | D22: Book a Demo | E22: Fix spacing on mobile | F22: Medium | G22: Pratyank | H22: Complete | J22: 46181 | L22: 46195 | N22: This is fixed on desktop but still showing issues on mobile.
B23: June 12 push | C23: Combine sections | D23: Book a Demo | E23: Combine the Request Your Brand and Book a Demo section into one. Remove the appt options and scheduling and just add that our Team will be in touch to book a demo and then the demo details from the Book a Demo section | F23: High | G23: Rafay | H23: Complete | J23: 46181 | L23: 46202
B24: June 12 push | C24: Add how did you hear about us | D24: Book a Demo | E24: Add Discord and input field for Other options for how did you hear about us | F24: Low | G24: Rafay -> Pratyank | H24: Complete | J24: 46181 | L24: 46233
C25: Date picker not selecting date | D25: Create Opportunity | E25: Fix error where date picker not selecting date | F25: Medium | G25: Rafay | H25: Not Started
C26: Days Alignment | D26: Create Opportunity | E26: Fix days alignment off | F26: Medium | G26: Rafay | H26: Not Started
B27: 46181 | C27: Fix upload image | D27: Create Opportunity | E27: upload image not working | F27: Medium | G27: Pratyank | H27: Not Started | J27: 46181
C28: Create New Accounts (Brand Owners) | D28: Signup/Login, Super Admin | E28: Fix so we can create new accounts with no issues and login to existing accounts with new issues. | F28: Medium | G28: Dhruv -> Jyotishmoy | H28: Complete | J28: 46188 | L28: 46216
C29: Create New Accounts (Fan Artists) | D29: Signup/Login, Super Admin | E29: Fix so we can create new accounts for fan artists with no issues. | F29: High | G29: Dhruv -> Jyotishmoy | H29: Complete | J29: 46188 | L29: 46216
C30: Test accounts | D30: Signup/Login, Dashboard | E30: Create test accounts for team to login | F30: High | G30: Dhruv -> Jyotishmoy | H30: Complete | J30: 46188
C31: Featured Campaigns style | D31: Home Page | E31: Update featured campaigns to remove the infringement images and template campaigns. Replace with feed of current/live campaigns or preset ones from old/new campaigns. | F31: High | G31: Rafay | H31: Complete | J31: 46188 | L31: 46202
C32: Select Featured Campaigns | D32: Super Admin | E32: Create a function for marking featured campaigns in the Super Admin | F32: High | G32: Dhruv | H32: In Progress | J32: 46188
C33: Featured Campaigns Section | D33: Home Page | E33: Create section for featured campaigns to display | F33: High | G33: Rafay | H33: Complete | J33: 46188 | L33: 46202
C34: Backend Migration | D34: Backend | E34: Migrating Node.js to Nest.js server architecture | F34: Medium | G34: Dhruv, Aakash | H34: Blocked | J34: 46188
C35: Signup Workflow | D35: Signup/Login | E35: Fix the registering of brand owners and fan artists accounts when signing up | F35: Medium | G35: Dhruv, Jyotishmoy | H35: Complete | J35: 46188 | L35: 46216
C36: Shift Manual Auth to Firebase | D36: Auth | E36: Shift the current manual auth apis to firebase sdk instead | F36: High | G36: Aakash | H36: Complete | J36: 46190 | L36: 46198
C37: Add Coolify to VPS | D37: Core/Devops | E37: Shift the projects and db to Coolify instead | F37: High | G37: Aakash | H37: Complete | J37: 46190 | L37: 46202
C38: Make a weekly database backup cron job | D38: DB Backups | E38: Add a weekly automated cron job that makes backup of the db and saves it locally on the VPS itself | F38: Medium | G38: Aakash | H38: Ready for Review | J38: 46190
C39: Update platform T&S date | D39: Terms of Service | E39: Platform Terms of Service date needs to be fixed: Updated June 23, 2026: https://www.modfanofficial.com/legal/terms-and-service | F39: Medium | G39: Pratyank | H39: Complete | J39: 46198 | L39: 46202
C40: Transfer/create submission terms of service and link to each Opportunity/contest page | D40: Terms of Service, Opportunity Pages | E40: Make sure the submissions terms of service has it’s own page and is linked for each contest/opportunity page: https://modfanart.com/pages/submission-terms-and-conditions (need to update “MOD INC.” name to “MOD Fan Official”. create a page for contest submissions terms, you can find the terms data in lib/terms-data/contestSubmissionSections.ts and use the terms-section.tsx component to display it | F40: High | G40: Pratyank | H40: Complete | J40: 46198 | L40: 46202
C41: Authentication for librarians page | D41: Authentication, The Librarians, Opportunty Page | E41: Authentication for the Librarians campaign page. Check if the are logged in for the page. | F41: High | G41: Pratyank | H41: Complete | J41: 46202 | L41: 46216
...

Sheet Weekly Summary
B1: Weekly Summary Dashboard
B3: Total Open Tasks | C3: Tasks In Progress | D3: Tasks Ready for Review
B4: =COUNTIFS('Log Tracker'!H4:H104, "<>Complete", 'Log Tracker'!H4:H104, "<>Merged", 'Log Tracker'!H4:H104, "<>") -> 18 | C4: =COUNTIF('Log Tracker'!H4:H104, "In Progress") -> 4 | D4: =COUNTIF('Log Tracker'!H4:H104, "Ready for Review") -> 4
B5: Tasks Merged | C5: Tasks Completed | D5: Completion Rate %
B6: =COUNTIF('Log Tracker'!H4:H104, "Merged") -> 1 | C6: =COUNTIF('Log Tracker'!H4:H104, "Complete") -> 69 | D6: =IF(COUNTA('Log Tracker'!H4:H104)=0, 0, (COUNTIF('Log Tracker'!H4:H104, "Complete") + COUNTIF('Log Tracker'!H4:H104, "Merged")) / COUNTA('Log Tracker'!H4:H104)) -> 0.79545455
B9: Week | C9: Team Member | D9: Tasks Assigned | E9: Tasks Completed | F9: Tasks Merged | G9: Tasks Carried Over | H9: Major Accomplishments | I9: Blockers | J9: Support Needed Next Week
B10: =IFERROR(__xludf.DUMMYFUNCTION("LET(tasks, 'Log Tracker'!C4:C1000, assignees, 'Log Tracker'!G4:G1000, status, 'Log Tracker'!H4:H1000, compDates, 'Log Tracker'!L4:L1000, blockers, 'Log Tracker'!O4:O1000, carry, 'Log Tracker'!Q4:Q1000, uniqueWeeks, SORT(UNIQUE(FILTER(compDates, compDates<"&">""""))), result, REDUCE({"""", """", """", """", """", """", """", """", """"}, uniqueWeeks, LAMBDA(acc, wk, LET(weekTasks, FILTER(tasks, compDates=wk), weekAssignees, FILTER(assignees, compDates=wk), weekStatus, FILTER(status, compDates=wk), weekBlocker"&"s, FILTER(blockers, compDates=wk), weekCarry, FILTER(carry, compDates=wk), assignedCount, COUNTA(weekTasks), completedCount, COUNTIF(weekStatus, ""Complete""), mergedCount, COUNTIF(weekStatus, ""Merged""), carryCount, COUNTIF(weekCarry, ""Y""), teamMember"&"s, TEXTJOIN("", "", TRUE, UNIQUE(weekAssignees)), accomplishments, TEXTJOIN("" | "", TRUE, weekTasks), blockersText, IFERROR(TEXTJOIN("" | "", TRUE, FILTER(weekBlockers, weekBlockers<>""N/A"", weekBlockers<>"""")), """"), VSTACK(acc, {wk, teamMembers, ass"&"ignedCount, completedCount, mergedCount, carryCount, accomplishments, blockersText, """"})))) , CHOOSEROWS(result, SEQUENCE(ROWS(result)-1, 1, 2)))"),46174) -> 46174 | C10: =IFERROR(__xludf.DUMMYFUNCTION("""COMPUTED_VALUE"""),"Joey") -> Joey | D10: =IFERROR(__xludf.DUMMYFUNCTION("""COMPUTED_VALUE"""),1) -> 1 | E10: =IFERROR(__xludf.DUMMYFUNCTION("""COMPUTED_VALUE"""),1) -> 1 | F10: =IFERROR(__xludf.DUMMYFUNCTION("""COMPUTED_VALUE"""),0) -> 0 | G10: =IFERROR(__xludf.DUMMYFUNCTION("""COMPUTED_VALUE"""),1) -> 1 | H10: =IFERROR(__xludf.DUMMYFUNCTION("""COMPUTED_VALUE"""),"Dev Log & Tracker") -> Dev Log & Tracker | I10: =IFERROR(__xludf.DUMMYFUNCTION("""COMPUTED_VALUE"""),"") | J10: =IFERROR(__xludf.DUMMYFUNCTION("""COMPUTED_VALUE"""),"")
B11: =IFERROR(__xludf.DUMMYFUNCTION("""COMPUTED_VALUE"""),46181) -> 46181 | C11: =IFERROR(__xludf.DUMMYFUNCTION("""COMPUTED_VALUE"""),"Rafay") -> Rafay | D11: =IFERROR(__xludf.DUMMYFUNCTION("""COMPUTED_VALUE"""),4) -> 4 | E11: =IFERROR(__xludf.DUMMYFUNCTION("""COMPUTED_VALUE"""),4) -> 4 | F11: =IFERROR(__xludf.DUMMYFUNCTION("""COMPUTED_VALUE"""),0) -> 0 | G11: =IFERROR(__xludf.DUMMYFUNCTION("""COMPUTED_VALUE"""),0) -> 0 | H11: =IFERROR(__xludf.DUMMYFUNCTION("""COMPUTED_VALUE"""),"Double footer | Update Buttons | Artist Logos | Nav Bar update") -> Double footer | Update Buttons | Artist Logos | Nav Bar update | I11: =IFERROR(__xludf.DUMMYFUNCTION("""COMPUTED_VALUE"""),"") | J11: =IFERROR(__xludf.DUMMYFUNCTION("""COMPUTED_VALUE"""),"")
B12: =IFERROR(__xludf.DUMMYFUNCTION("""COMPUTED_VALUE"""),46195) -> 46195 | C12: =IFERROR(__xludf.DUMMYFUNCTION("""COMPUTED_VALUE"""),"Rafay, Pratyank") -> Rafay, Pratyank | D12: =IFERROR(__xludf.DUMMYFUNCTION("""COMPUTED_VALUE"""),3) -> 3 | E12: =IFERROR(__xludf.DUMMYFUNCTION("""COMPUTED_VALUE"""),3) -> 3 | F12: =IFERROR(__xludf.DUMMYFUNCTION("""COMPUTED_VALUE"""),0) -> 0 | G12: =IFERROR(__xludf.DUMMYFUNCTION("""COMPUTED_VALUE"""),0) -> 0 | H12: =IFERROR(__xludf.DUMMYFUNCTION("""COMPUTED_VALUE"""),"Page spacing | Clean up Mobile | Mobile page spacing") -> Page spacing | Clean up Mobile | Mobile page spacing | I12: =IFERROR(__xludf.DUMMYFUNCTION("""COMPUTED_VALUE"""),"") | J12: =IFERROR(__xludf.DUMMYFUNCTION("""COMPUTED_VALUE"""),"")
B13: =IFERROR(__xludf.DUMMYFUNCTION("""COMPUTED_VALUE"""),46198) -> 46198 | C13: =IFERROR(__xludf.DUMMYFUNCTION("""COMPUTED_VALUE"""),"Aakash") -> Aakash | D13: =IFERROR(__xludf.DUMMYFUNCTION("""COMPUTED_VALUE"""),1) -> 1 | E13: =IFERROR(__xludf.DUMMYFUNCTION("""COMPUTED_VALUE"""),1) -> 1 | F13: =IFERROR(__xludf.DUMMYFUNCTION("""COMPUTED_VALUE"""),0) -> 0 | G13: =IFERROR(__xludf.DUMMYFUNCTION("""COMPUTED_VALUE"""),0) -> 0 | H13: =IFERROR(__xludf.DUMMYFUNCTION("""COMPUTED_VALUE"""),"Shift Manual Auth to Firebase") -> Shift Manual Auth to Firebase | I13: =IFERROR(__xludf.DUMMYFUNCTION("""COMPUTED_VALUE"""),"") | J13: =IFERROR(__xludf.DUMMYFUNCTION("""COMPUTED_VALUE"""),"")
B14: =IFERROR(__xludf.DUMMYFUNCTION("""COMPUTED_VALUE"""),46202) -> 46202 | C14: =IFERROR(__xludf.DUMMYFUNCTION("""COMPUTED_VALUE"""),"Pratyank, Rafay, Aakash") -> Pratyank, Rafay, Aakash | D14: =IFERROR(__xludf.DUMMYFUNCTION("""COMPUTED_VALUE"""),11) -> 11 | E14: =IFERROR(__xludf.DUMMYFUNCTION("""COMPUTED_VALUE"""),11) -> 11 | F14: =IFERROR(__xludf.DUMMYFUNCTION("""COMPUTED_VALUE"""),0) -> 0 | G14: =IFERROR(__xludf.DUMMYFUNCTION("""COMPUTED_VALUE"""),0) -> 0 | H14: =IFERROR(__xludf.DUMMYFUNCTION("""COMPUTED_VALUE"""),"Update Image | Remove some sections | Discord link | Guidelines PDF | Update Section | Combine sections | Featured Campaigns style | Featured Campaigns Section | Add Coolify to VPS | Update platform T&S date | Transfer/create submission terms of service"&" and link to each Opportunity/contest page") -> Update Image | Remove some sections | Discord link | Guidelines PDF | Update Section | Combine sections | Featured Campaigns style | Featured Campaigns Section | Add Coolify to VPS | Update platform T&S date | Transfer/create submission terms of service and link to each Opportunity/contest page | I14: =IFERROR(__xludf.DUMMYFUNCTION("""COMPUTED_VALUE"""),"") | J14: =IFERROR(__xludf.DUMMYFUNCTION("""COMPUTED_VALUE"""),"")
B15: =IFERROR(__xludf.DUMMYFUNCTION("""COMPUTED_VALUE"""),46203) -> 46203 | C15: =IFERROR(__xludf.DUMMYFUNCTION("""COMPUTED_VALUE"""),"Aakash") -> Aakash | D15: =IFERROR(__xludf.DUMMYFUNCTION("""COMPUTED_VALUE"""),1) -> 1 | E15: =IFERROR(__xludf.DUMMYFUNCTION("""COMPUTED_VALUE"""),1) -> 1 | F15: =IFERROR(__xludf.DUMMYFUNCTION("""COMPUTED_VALUE"""),0) -> 0 | G15: =IFERROR(__xludf.DUMMYFUNCTION("""COMPUTED_VALUE"""),0) -> 0 | H15: =IFERROR(__xludf.DUMMYFUNCTION("""COMPUTED_VALUE"""),"Switch domain to hostinger") -> Switch domain to hostinger | I15: =IFERROR(__xludf.DUMMYFUNCTION("""COMPUTED_VALUE"""),"") | J15: =IFERROR(__xludf.DUMMYFUNCTION("""COMPUTED_VALUE"""),"")
B16: =IFERROR(__xludf.DUMMYFUNCTION("""COMPUTED_VALUE"""),46216) -> 46216 | C16: =IFERROR(__xludf.DUMMYFUNCTION("""COMPUTED_VALUE"""),"Dhruv -> Jyotishmoy, Dhruv, Jyotishmoy, Pratyank, Jyotishmoy, Jyotishmoy, Aakash") -> Dhruv -> Jyotishmoy, Dhruv, Jyotishmoy, Pratyank, Jyotishmoy, Jyotishmoy, Aakash | D16: =IFERROR(__xludf.DUMMYFUNCTION("""COMPUTED_VALUE"""),7) -> 7 | E16: =IFERROR(__xludf.DUMMYFUNCTION("""COMPUTED_VALUE"""),7) -> 7 | F16: =IFERROR(__xludf.DUMMYFUNCTION("""COMPUTED_VALUE"""),0) -> 0 | G16: =IFERROR(__xludf.DUMMYFUNCTION("""COMPUTED_VALUE"""),0) -> 0 | H16: =IFERROR(__xludf.DUMMYFUNCTION("""COMPUTED_VALUE"""),"Create New Accounts (Brand Owners) | Create New Accounts (Fan Artists) | Signup Workflow | Authentication for librarians page | Fix signup | Fix Lib contest entry | Get Submission flow ready") -> Create New Accounts (Brand Owners) | Create New Accounts (Fan Artists) | Signup Workflow | Authentication for librarians page | Fix signup | Fix Lib contest entry | Get Submission flow ready | I16: =IFERROR(__xludf.DUMMYFUNCTION("""COMPUTED_VALUE"""),"") | J16: =IFERROR(__xludf.DUMMYFUNCTION("""COMPUTED_VALUE"""),"")
B17: =IFERROR(__xludf.DUMMYFUNCTION("""COMPUTED_VALUE"""),46219) -> 46219 | C17: =IFERROR(__xludf.DUMMYFUNCTION("""COMPUTED_VALUE"""),"Rafay") -> Rafay | D17: =IFERROR(__xludf.DUMMYFUNCTION("""COMPUTED_VALUE"""),1) -> 1 | E17: =IFERROR(__xludf.DUMMYFUNCTION("""COMPUTED_VALUE"""),1) -> 1 | F17: =IFERROR(__xludf.DUMMYFUNCTION("""COMPUTED_VALUE"""),0) -> 0 | G17: =IFERROR(__xludf.DUMMYFUNCTION("""COMPUTED_VALUE"""),0) -> 0 | H17: =IFERROR(__xludf.DUMMYFUNCTION("""COMPUTED_VALUE"""),"Fix refresh glitch ") -> Fix refresh glitch | I17: =IFERROR(__xludf.DUMMYFUNCTION("""COMPUTED_VALUE"""),"") | J17: =IFERROR(__xludf.DUMMYFUNCTION("""COMPUTED_VALUE"""),"")
B18: =IFERROR(__xludf.DUMMYFUNCTION("""COMPUTED_VALUE"""),46223) -> 46223 | C18: =IFERROR(__xludf.DUMMYFUNCTION("""COMPUTED_VALUE"""),"Rafay, Pratyank, Praytank") -> Rafay, Pratyank, Praytank | D18: =IFERROR(__xludf.DUMMYFUNCTION("""COMPUTED_VALUE"""),5) -> 5 | E18: =IFERROR(__xludf.DUMMYFUNCTION("""COMPUTED_VALUE"""),5) -> 5 | F18: =IFERROR(__xludf.DUMMYFUNCTION("""COMPUTED_VALUE"""),0) -> 0 | G18: =IFERROR(__xludf.DUMMYFUNCTION("""COMPUTED_VALUE"""),0) -> 0 | H18: =IFERROR(__xludf.DUMMYFUNCTION("""COMPUTED_VALUE"""),"Remove sections in Profile | User name visibility fix | Remove for Creators page on mobile | Remove hardcoded parts of the Dashboard | Add description and note to contest entry") -> Remove sections in Profile | User name visibility fix | Remove for Creators page on mobile | Remove hardcoded parts of the Dashboard | Add description and note to contest entry | I18: =IFERROR(__xludf.DUMMYFUNCTION("""COMPUTED_VALUE"""),"") | J18: =IFERROR(__xludf.DUMMYFUNCTION("""COMPUTED_VALUE"""),"")
B19: =IFERROR(__xludf.DUMMYFUNCTION("""COMPUTED_VALUE"""),46233) -> 46233 | C19: =IFERROR(__xludf.DUMMYFUNCTION("""COMPUTED_VALUE"""),"Rafay -> Pratyank, Pratyank") -> Rafay -> Pratyank, Pratyank | D19: =IFERROR(__xludf.DUMMYFUNCTION("""COMPUTED_VALUE"""),4) -> 4 | E19: =IFERROR(__xludf.DUMMYFUNCTION("""COMPUTED_VALUE"""),4) -> 4 | F19: =IFERROR(__xludf.DUMMYFUNCTION("""COMPUTED_VALUE"""),0) -> 0 | G19: =IFERROR(__xludf.DUMMYFUNCTION("""COMPUTED_VALUE"""),0) -> 0 | H19: =IFERROR(__xludf.DUMMYFUNCTION("""COMPUTED_VALUE"""),"Add how did you hear about us | Replace hero image at Signup | Fix submission tags | Complete migration away from AWS") -> Add how did you hear about us | Replace hero image at Signup | Fix submission tags | Complete migration away from AWS | I19: =IFERROR(__xludf.DUMMYFUNCTION("""COMPUTED_VALUE"""),"") | J19: =IFERROR(__xludf.DUMMYFUNCTION("""COMPUTED_VALUE"""),"")
B20: =IFERROR(__xludf.DUMMYFUNCTION("""COMPUTED_VALUE"""),46236) -> 46236 | C20: =IFERROR(__xludf.DUMMYFUNCTION("""COMPUTED_VALUE"""),"Pratyank") -> Pratyank | D20: =IFERROR(__xludf.DUMMYFUNCTION("""COMPUTED_VALUE"""),1) -> 1 | E20: =IFERROR(__xludf.DUMMYFUNCTION("""COMPUTED_VALUE"""),1) -> 1 | F20: =IFERROR(__xludf.DUMMYFUNCTION("""COMPUTED_VALUE"""),0) -> 0 | G20: =IFERROR(__xludf.DUMMYFUNCTION("""COMPUTED_VALUE"""),0) -> 0 | H20: =IFERROR(__xludf.DUMMYFUNCTION("""COMPUTED_VALUE"""),"Link T&S to Lib contest") -> Link T&S to Lib contest | I20: =IFERROR(__xludf.DUMMYFUNCTION("""COMPUTED_VALUE"""),"") | J20: =IFERROR(__xludf.DUMMYFUNCTION("""COMPUTED_VALUE"""),"")
B21: =IFERROR(__xludf.DUMMYFUNCTION("""COMPUTED_VALUE"""),46244) -> 46244 | C21: =IFERROR(__xludf.DUMMYFUNCTION("""COMPUTED_VALUE"""),"Pratyank, Praytank, Rafay") -> Pratyank, Praytank, Rafay | D21: =IFERROR(__xludf.DUMMYFUNCTION("""COMPUTED_VALUE"""),6) -> 6 | E21: =IFERROR(__xludf.DUMMYFUNCTION("""COMPUTED_VALUE"""),6) -> 6 | F21: =IFERROR(__xludf.DUMMYFUNCTION("""COMPUTED_VALUE"""),0) -> 0 | G21: =IFERROR(__xludf.DUMMYFUNCTION("""COMPUTED_VALUE"""),0) -> 0 | H21: =IFERROR(__xludf.DUMMYFUNCTION("""COMPUTED_VALUE"""),"Remove Welcome Art | Fix submission images in dashboard | Individual submission pages | Dashboard - View All Submissions | Submission Detail View - Full Image + Form Metadata | Fix dashboard images") -> Remove Welcome Art | Fix submission images in dashboard | Individual submission pages | Dashboard - View All Submissions | Submission Detail View - Full Image + Form Metadata | Fix dashboard images | I21: =IFERROR(__xludf.DUMMYFUNCTION("""COMPUTED_VALUE"""),"") | J21: =IFERROR(__xludf.DUMMYFUNCTION("""COMPUTED_VALUE"""),"")
B22: =IFERROR(__xludf.DUMMYFUNCTION("""COMPUTED_VALUE"""),46258) -> 46258 | C22: =IFERROR(__xludf.DUMMYFUNCTION("""COMPUTED_VALUE"""),"Rafay, Pratyank") -> Rafay, Pratyank | D22: =IFERROR(__xludf.DUMMYFUNCTION("""COMPUTED_VALUE"""),4) -> 4 | E22: =IFERROR(__xludf.DUMMYFUNCTION("""COMPUTED_VALUE"""),4) -> 4 | F22: =IFERROR(__xludf.DUMMYFUNCTION("""COMPUTED_VALUE"""),0) -> 0 | G22: =IFERROR(__xludf.DUMMYFUNCTION("""COMPUTED_VALUE"""),0) -> 0 | H22: =IFERROR(__xludf.DUMMYFUNCTION("""COMPUTED_VALUE"""),"Prepare judging system | Judging backend endpoints | Judging next phase | Copy judging password") -> Prepare judging system | Judging backend endpoints | Judging next phase | Copy judging password | I22: =IFERROR(__xludf.DUMMYFUNCTION("""COMPUTED_VALUE"""),"") | J22: =IFERROR(__xludf.DUMMYFUNCTION("""COMPUTED_VALUE"""),"")
B23: =IFERROR(__xludf.DUMMYFUNCTION("""COMPUTED_VALUE"""),46261) -> 46261 | C23: =IFERROR(__xludf.DUMMYFUNCTION("""COMPUTED_VALUE"""),"Dhruv") -> Dhruv | D23: =IFERROR(__xludf.DUMMYFUNCTION("""COMPUTED_VALUE"""),1) -> 1 | E23: =IFERROR(__xludf.DUMMYFUNCTION("""COMPUTED_VALUE"""),0) -> 0 | F23: =IFERROR(__xludf.DUMMYFUNCTION("""COMPUTED_VALUE"""),0) -> 0 | G23: =IFERROR(__xludf.DUMMYFUNCTION("""COMPUTED_VALUE"""),0) -> 0 | H23: =IFERROR(__xludf.DUMMYFUNCTION("""COMPUTED_VALUE"""),"Licensing workflow doc") -> Licensing workflow doc | I23: =IFERROR(__xludf.DUMMYFUNCTION("""COMPUTED_VALUE"""),"") | J23: =IFERROR(__xludf.DUMMYFUNCTION("""COMPUTED_VALUE"""),"")
B24: =IFERROR(__xludf.DUMMYFUNCTION("""COMPUTED_VALUE"""),46265) -> 46265 | C24: =IFERROR(__xludf.DUMMYFUNCTION("""COMPUTED_VALUE"""),"Rafay") -> Rafay | D24: =IFERROR(__xludf.DUMMYFUNCTION("""COMPUTED_VALUE"""),1) -> 1 | E24: =IFERROR(__xludf.DUMMYFUNCTION("""COMPUTED_VALUE"""),1) -> 1 | F24: =IFERROR(__xludf.DUMMYFUNCTION("""COMPUTED_VALUE"""),0) -> 0 | G24: =IFERROR(__xludf.DUMMYFUNCTION("""COMPUTED_VALUE"""),0) -> 0 | H24: =IFERROR(__xludf.DUMMYFUNCTION("""COMPUTED_VALUE"""),"PDF image preview") -> PDF image preview | I24: =IFERROR(__xludf.DUMMYFUNCTION("""COMPUTED_VALUE"""),"") | J24: =IFERROR(__xludf.DUMMYFUNCTION("""COMPUTED_VALUE"""),"")
